<?xml version="1.0" ?>
<!-- =================================================================================== -->
<!-- |    This document was autogenerated by xacro from my_bot.sdf.xacro               | -->
<!-- |    EDITING THIS FILE BY HAND IS NOT RECOMMENDED                                 | -->
<!-- =================================================================================== -->
<sdf version="1.8">
  <world name="bot_world">
    <physics name="1ms" type="ignored">
      <max_step_size>0.005</max_step_size>
      <real_time_factor>1.0</real_time_factor>
    </physics>
    <plugin filename="libignition-gazebo-physics-system.so" name="ignition::gazebo::systems::Physics">
        </plugin>
    <plugin filename="libignition-gazebo-user-commands-system.so" name="ignition::gazebo::systems::UserCommands">
        </plugin>
    <plugin filename="libignition-gazebo-scene-broadcaster-system.so" name="ignition::gazebo::systems::SceneBroadcaster">
        </plugin>
    <light name="sun" type="directional">
      <cast_shadows>true</cast_shadows>
      <pose>0 0 10 0 0 0</pose>
      <diffuse>0.8 0.8 0.8 1</diffuse>
      <specular>0.2 0.2 0.2 1</specular>
      <attenuation>
        <range>1000</range>
        <constant>0.9</constant>
        <linear>0.01</linear>
        <quadratic>0.001</quadratic>
      </attenuation>
      <direction>-0.5 0.1 -0.9</direction>
    </light>
    <model name="ground_plane">
      <static>true</static>
      <link name="link">
        <collision name="collision">
          <geometry>
            <plane>
              <normal>0 0 1</normal>
            </plane>
          </geometry>
        </collision>
        <visual name="visual">
          <geometry>
            <plane>
              <normal>0 0 1</normal>
              <size>10 10</size>
            </plane>
          </geometry>
          <material>
            <ambient>0.8 0.8 0.8 1</ambient>
            <diffuse>0.8 0.8 0.8 1</diffuse>
            <specular>0.8 0.8 0.8 1</specular>
          </material>
        </visual>
      </link>
    </model>
    <model canonical_link="base_link" name="skipper">
      <pose relative_to="world">0 0 0 0 0 0</pose>
      <link name="base_link">
        <pose relative_to="__model__">0 0 0 0 0 0</pose>
        <inertial>
          <!--inertial properties of the link mass, inertia matix-->
          <mass>0.123</mass>
          <pose>0 0 0.019 0 0 0</pose>
          <inertia>
            <ixx>0.00015</ixx>
            <ixy>0</ixy>
            <ixz>0</ixz>
            <iyy>0.00015</iyy>
            <iyz>0</iyz>
            <izz>0.00025</izz>
          </inertia>
        </inertial>
        <visual name="visual">
          <pose>0 0 0.019 0 0 0</pose>
          <geometry>
            <cylinder>
              <radius>0.050</radius>
              <length>0.038</length>
            </cylinder>
          </geometry>
          <material>
            <ambient>0.0 0.0 1.0 1</ambient>
            <diffuse>0.0 0.0 1.0 1</diffuse>
            <specular>0.0 0.0 1.0 1</specular>
          </material>
        </visual>
        <!--
            <collision name='collision'>
                <pose>0 0 0.025 0 0 0</pose>
                <geometry>
                    <cylinder>
                        <radius>0.050</radius>
                        <length>0.050</length>
                    </cylinder>
                </geometry>
            </collision>
            -->
      </link>
      <link name="base_collision1_link">
        <pose relative_to="base_link">-0.081 0.008 0.0025 0 0 0</pose>
        <inertial>
          <mass>0.001</mass>
          <pose>0 0 0 0 0 0</pose>
          <inertia>
            <ixx>0.0000041</ixx>
            <ixy>0</ixy>
            <ixz>0</ixz>
            <iyy>0.00000033</iyy>
            <iyz>0</iyz>
            <izz>0.0000039</izz>
          </inertia>
        </inertial>
        <visual name="visual">
          <pose>0 0 0 0 0 0</pose>
          <geometry>
            <sphere>
              <radius>0.0025</radius>
            </sphere>
          </geometry>
          <material>
            <ambient>1.0 0.0 1.0 1</ambient>
            <diffuse>1.0 0.0 1.0 1</diffuse>
            <specular>1.0 0.0 1.0 1</specular>
          </material>
        </visual>
        <collision name="collision">
          <pose>0 0 0 0 0 0</pose>
          <geometry>
            <sphere>
              <radius>0.0025</radius>
            </sphere>
          </geometry>
          <surface>
            <friction>
              <ode>
                <mu>0.75</mu>
                <mu2>0.75</mu2>
              </ode>
            </friction>
          </surface>
        </collision>
      </link>
      <joint name="base_collision1_joint" type="fixed">
        <pose relative_to="base_collision1_link"/>
        <parent>base_link</parent>
        <child>base_collision1_link</child>
      </joint>
      <link name="base_collision2_link">
        <pose relative_to="base_link">0.033 0.074 0.0025 0 0 0</pose>
        <inertial>
          <mass>0.001</mass>
          <pose>0 0 0 0 0 0</pose>
          <inertia>
            <ixx>0.0000041</ixx>
            <ixy>0</ixy>
            <ixz>0</ixz>
            <iyy>0.00000033</iyy>
            <iyz>0</iyz>
            <izz>0.0000039</izz>
          </inertia>
        </inertial>
        <visual name="visual">
          <pose>0 0 0 0 0 0</pose>
          <geometry>
            <sphere>
              <radius>0.0025</radius>
            </sphere>
          </geometry>
          <material>
            <ambient>1.0 0.0 1.0 1</ambient>
            <diffuse>1.0 0.0 1.0 1</diffuse>
            <specular>1.0 0.0 1.0 1</specular>
          </material>
        </visual>
        <collision name="collision">
          <pose>0 0 0 0 0 0</pose>
          <geometry>
            <sphere>
              <radius>0.0025</radius>
            </sphere>
          </geometry>
          <surface>
            <friction>
              <ode>
                <mu>0.75</mu>
                <mu2>0.75</mu2>
              </ode>
            </friction>
          </surface>
        </collision>
      </link>
      <joint name="base_collision2_joint" type="fixed">
        <pose relative_to="base_collision2_link"/>
        <parent>base_link</parent>
        <child>base_collision2_link</child>
      </joint>
      <link name="base_collision3_link">
        <pose relative_to="base_link">0.0475 0.066 0.0025 0 0 0</pose>
        <inertial>
          <mass>0.001</mass>
          <pose>0 0 0 0 0 0</pose>
          <inertia>
            <ixx>0.0000041</ixx>
            <ixy>0</ixy>
            <ixz>0</ixz>
            <iyy>0.00000033</iyy>
            <iyz>0</iyz>
            <izz>0.0000039</izz>
          </inertia>
        </inertial>
        <visual name="visual">
          <pose>0 0 0 0 0 0</pose>
          <geometry>
            <sphere>
              <radius>0.0025</radius>
            </sphere>
          </geometry>
          <material>
            <ambient>1.0 0.0 1.0 1</ambient>
            <diffuse>1.0 0.0 1.0 1</diffuse>
            <specular>1.0 0.0 1.0 1</specular>
          </material>
        </visual>
        <collision name="collision">
          <pose>0 0 0 0 0 0</pose>
          <geometry>
            <sphere>
              <radius>0.0025</radius>
            </sphere>
          </geometry>
          <surface>
            <friction>
              <ode>
                <mu>0.75</mu>
                <mu2>0.75</mu2>
              </ode>
            </friction>
          </surface>
        </collision>
      </link>
      <joint name="base_collision3_joint" type="fixed">
        <pose relative_to="base_collision3_link"/>
        <parent>base_link</parent>
        <child>base_collision3_link</child>
      </joint>
      <link name="base_collision4_link">
        <pose relative_to="base_link">0.0475 -0.066 0.0025 0 0 0</pose>
        <inertial>
          <mass>0.001</mass>
          <pose>0 0 0 0 0 0</pose>
          <inertia>
            <ixx>0.0000041</ixx>
            <ixy>0</ixy>
            <ixz>0</ixz>
            <iyy>0.00000033</iyy>
            <iyz>0</iyz>
            <izz>0.0000039</izz>
          </inertia>
        </inertial>
        <visual name="visual">
          <pose>0 0 0 0 0 0</pose>
          <geometry>
            <sphere>
              <radius>0.0025</radius>
            </sphere>
          </geometry>
          <material>
            <ambient>1.0 0.0 1.0 1</ambient>
            <diffuse>1.0 0.0 1.0 1</diffuse>
            <specular>1.0 0.0 1.0 1</specular>
          </material>
        </visual>
        <collision name="collision">
          <pose>0 0 0 0 0 0</pose>
          <geometry>
            <sphere>
              <radius>0.0025</radius>
            </sphere>
          </geometry>
          <surface>
            <friction>
              <ode>
                <mu>0.75</mu>
                <mu2>0.75</mu2>
              </ode>
            </friction>
          </surface>
        </collision>
      </link>
      <joint name="base_collision4_joint" type="fixed">
        <pose relative_to="base_collision4_link"/>
        <parent>base_link</parent>
        <child>base_collision4_link</child>
      </joint>
      <link name="base_collision5_link">
        <pose relative_to="base_link">0.033 -0.074 0.0025 0 0 0</pose>
        <inertial>
          <mass>0.001</mass>
          <pose>0 0 0 0 0 0</pose>
          <inertia>
            <ixx>0.0000041</ixx>
            <ixy>0</ixy>
            <ixz>0</ixz>
            <iyy>0.00000033</iyy>
            <iyz>0</iyz>
            <izz>0.0000039</izz>
          </inertia>
        </inertial>
        <visual name="visual">
          <pose>0 0 0 0 0 0</pose>
          <geometry>
            <sphere>
              <radius>0.0025</radius>
            </sphere>
          </geometry>
          <material>
            <ambient>1.0 0.0 1.0 1</ambient>
            <diffuse>1.0 0.0 1.0 1</diffuse>
            <specular>1.0 0.0 1.0 1</specular>
          </material>
        </visual>
        <collision name="collision">
          <pose>0 0 0 0 0 0</pose>
          <geometry>
            <sphere>
              <radius>0.0025</radius>
            </sphere>
          </geometry>
          <surface>
            <friction>
              <ode>
                <mu>0.75</mu>
                <mu2>0.75</mu2>
              </ode>
            </friction>
          </surface>
        </collision>
      </link>
      <joint name="base_collision5_joint" type="fixed">
        <pose relative_to="base_collision5_link"/>
        <parent>base_link</parent>
        <child>base_collision5_link</child>
      </joint>
      <link name="base_collision6_link">
        <pose relative_to="base_link">-0.081 -0.008 0.0025 0 0 0</pose>
        <inertial>
          <mass>0.001</mass>
          <pose>0 0 0 0 0 0</pose>
          <inertia>
            <ixx>0.0000041</ixx>
            <ixy>0</ixy>
            <ixz>0</ixz>
            <iyy>0.00000033</iyy>
            <iyz>0</iyz>
            <izz>0.0000039</izz>
          </inertia>
        </inertial>
        <visual name="visual">
          <pose>0 0 0 0 0 0</pose>
          <geometry>
            <sphere>
              <radius>0.0025</radius>
            </sphere>
          </geometry>
          <material>
            <ambient>1.0 0.0 1.0 1</ambient>
            <diffuse>1.0 0.0 1.0 1</diffuse>
            <specular>1.0 0.0 1.0 1</specular>
          </material>
        </visual>
        <collision name="collision">
          <pose>0 0 0 0 0 0</pose>
          <geometry>
            <sphere>
              <radius>0.0025</radius>
            </sphere>
          </geometry>
          <surface>
            <friction>
              <ode>
                <mu>0.75</mu>
                <mu2>0.75</mu2>
              </ode>
            </friction>
          </surface>
        </collision>
      </link>
      <joint name="base_collision6_joint" type="fixed">
        <pose relative_to="base_collision6_link"/>
        <parent>base_link</parent>
        <child>base_collision6_link</child>
      </joint>
      <link name="servo1_link">
        <pose relative_to="base_link">-0.06899 0.0475 0.033 0 -0.349066 2.0944</pose>
        <inertial>
          <!--inertial properties of the link mass, inertia matix-->
          <pose>-0.023 -0.010 0 0 0 0</pose>
          <mass>0.060</mass>
          <inertia>
            <ixx>0.00001</ixx>
            <ixy>0</ixy>
            <ixz>0</ixz>
            <iyy>0.0000065</iyy>
            <iyz>0</iyz>
            <izz>0.0000125</izz>
          </inertia>
        </inertial>
        <visual name="visual">
          <pose>-0.023 -0.010 0 0 0 0</pose>
          <geometry>
            <box>
              <size>0.030 0.040 0.020</size>
            </box>
          </geometry>
          <material>
            <ambient>0.0 1.0 0.0 1</ambient>
            <diffuse>0.0 1.0 0.0 1</diffuse>
            <specular>0.0 1.0 0.0 1</specular>
          </material>
        </visual>
        <!--
                <collision name='collision'>
                    <pose>-0.023 -0.010 0 0 0 0</pose>
                    <geometry>
                        <box>
                            <size>0.030 0.040 0.020</size>
                        </box>
                    </geometry>
                </collision>
                -->
      </link>
      <joint name="servo1_joint" type="fixed">
        <pose relative_to="servo1_link"/>
        <parent>base_link</parent>
        <child>servo1_link</child>
      </joint>
      <link name="arm1_link">
        <pose relative_to="servo1_link"/>
        <inertial>
          <mass>0.008</mass>
          <pose>0 0.0325 0 0 0 0</pose>
          <inertia>
            <ixx>0.0000041</ixx>
            <ixy>0</ixy>
            <ixz>0</ixz>
            <iyy>0.00000033</iyy>
            <iyz>0</iyz>
            <izz>0.0000039</izz>
          </inertia>
        </inertial>
        <visual name="visual">
          <pose>0 0.0325 0 1.5708 0 0</pose>
          <geometry>
            <cylinder>
              <radius>0.0030</radius>
              <length>0.065</length>
            </cylinder>
          </geometry>
          <material>
            <ambient>0.0 0.0 1.0 1</ambient>
            <diffuse>0.0 0.0 1.0 1</diffuse>
            <specular>0.0 0.0 1.0 1</specular>
          </material>
        </visual>
        <!--
                <collision name='collision'>
                    <pose>0 ${arm_length / 2 } 0 1.5708 0 0</pose>
                    <geometry>
                        <cylinder>
                            <radius>0.0050</radius>
                            <length>${arm_length}</length>
                        </cylinder>
                    </geometry>
                </collision>
                -->
      </link>
      <joint name="arm1_joint" type="revolute">
        <pose relative_to="arm1_link"/>
        <parent>servo1_link</parent>
        <child>arm1_link</child>
        <axis>
          <xyz expressed_in="arm1_link">1 0 0</xyz>
          <limit>
            <lower>-1.25</lower>
            <upper>1.25</upper>
          </limit>
          <dynamics>
            <friction>0.05</friction>
            <damping>0.04</damping>
          </dynamics>
        </axis>
      </joint>
      <plugin filename="libignition-gazebo-joint-position-controller-system.so" name="ignition::gazebo::systems::JointPositionController">
        <joint_name>arm1_joint</joint_name>
        <joint_index>0</joint_index>
        <p_gain>20</p_gain>
        <i_gain>0.0</i_gain>
        <d_gain>0.0</d_gain>
      </plugin>
      <link name="servo2_link">
        <pose relative_to="base_link">-0.00664 0.0835 0.033 3.14159 -0.349066 2.0944</pose>
        <inertial>
          <!--inertial properties of the link mass, inertia matix-->
          <pose>-0.023 -0.010 0 0 0 0</pose>
          <mass>0.060</mass>
          <inertia>
            <ixx>0.00001</ixx>
            <ixy>0</ixy>
            <ixz>0</ixz>
            <iyy>0.0000065</iyy>
            <iyz>0</iyz>
            <izz>0.0000125</izz>
          </inertia>
        </inertial>
        <visual name="visual">
          <pose>-0.023 -0.010 0 0 0 0</pose>
          <geometry>
            <box>
              <size>0.030 0.040 0.020</size>
            </box>
          </geometry>
          <material>
            <ambient>0.0 1.0 0.0 1</ambient>
            <diffuse>0.0 1.0 0.0 1</diffuse>
            <specular>0.0 1.0 0.0 1</specular>
          </material>
        </visual>
        <!--
                <collision name='collision'>
                    <pose>-0.023 -0.010 0 0 0 0</pose>
                    <geometry>
                        <box>
                            <size>0.030 0.040 0.020</size>
                        </box>
                    </geometry>
                </collision>
                -->
      </link>
      <joint name="servo2_joint" type="fixed">
        <pose relative_to="servo2_link"/>
        <parent>base_link</parent>
        <child>servo2_link</child>
      </joint>
      <link name="arm2_link">
        <pose relative_to="servo2_link"/>
        <inertial>
          <mass>0.008</mass>
          <pose>0 0.0325 0 0 0 0</pose>
          <inertia>
            <ixx>0.0000041</ixx>
            <ixy>0</ixy>
            <ixz>0</ixz>
            <iyy>0.00000033</iyy>
            <iyz>0</iyz>
            <izz>0.0000039</izz>
          </inertia>
        </inertial>
        <visual name="visual">
          <pose>0 0.0325 0 1.5708 0 0</pose>
          <geometry>
            <cylinder>
              <radius>0.0030</radius>
              <length>0.065</length>
            </cylinder>
          </geometry>
          <material>
            <ambient>0.0 0.0 1.0 1</ambient>
            <diffuse>0.0 0.0 1.0 1</diffuse>
            <specular>0.0 0.0 1.0 1</specular>
          </material>
        </visual>
        <!--
                <collision name='collision'>
                    <pose>0 ${arm_length / 2 } 0 1.5708 0 0</pose>
                    <geometry>
                        <cylinder>
                            <radius>0.0050</radius>
                            <length>${arm_length}</length>
                        </cylinder>
                    </geometry>
                </collision>
                -->
      </link>
      <joint name="arm2_joint" type="revolute">
        <pose relative_to="arm2_link"/>
        <parent>servo2_link</parent>
        <child>arm2_link</child>
        <axis>
          <xyz expressed_in="arm2_link">1 0 0</xyz>
          <limit>
            <lower>-1.25</lower>
            <upper>1.25</upper>
          </limit>
          <dynamics>
            <friction>0.05</friction>
            <damping>0.04</damping>
          </dynamics>
        </axis>
      </joint>
      <plugin filename="libignition-gazebo-joint-position-controller-system.so" name="ignition::gazebo::systems::JointPositionController">
        <joint_name>arm2_joint</joint_name>
        <joint_index>0</joint_index>
        <p_gain>20</p_gain>
        <i_gain>0.0</i_gain>
        <d_gain>0.0</d_gain>
      </plugin>
      <link name="servo3_link">
        <pose relative_to="base_link">0.07563 0.036 0.033 0 -0.349066 0</pose>
        <inertial>
          <!--inertial properties of the link mass, inertia matix-->
          <pose>-0.023 -0.010 0 0 0 0</pose>
          <mass>0.060</mass>
          <inertia>
            <ixx>0.00001</ixx>
            <ixy>0</ixy>
            <ixz>0</ixz>
            <iyy>0.0000065</iyy>
            <iyz>0</iyz>
            <izz>0.0000125</izz>
          </inertia>
        </inertial>
        <visual name="visual">
          <pose>-0.023 -0.010 0 0 0 0</pose>
          <geometry>
            <box>
              <size>0.030 0.040 0.020</size>
            </box>
          </geometry>
          <material>
            <ambient>0.0 1.0 0.0 1</ambient>
            <diffuse>0.0 1.0 0.0 1</diffuse>
            <specular>0.0 1.0 0.0 1</specular>
          </material>
        </visual>
        <!--
                <collision name='collision'>
                    <pose>-0.023 -0.010 0 0 0 0</pose>
                    <geometry>
                        <box>
                            <size>0.030 0.040 0.020</size>
                        </box>
                    </geometry>
                </collision>
                -->
      </link>
      <joint name="servo3_joint" type="fixed">
        <pose relative_to="servo3_link"/>
        <parent>base_link</parent>
        <child>servo3_link</child>
      </joint>
      <link name="arm3_link">
        <pose relative_to="servo3_link"/>
        <inertial>
          <mass>0.008</mass>
          <pose>0 0.0325 0 0 0 0</pose>
          <inertia>
            <ixx>0.0000041</ixx>
            <ixy>0</ixy>
            <ixz>0</ixz>
            <iyy>0.00000033</iyy>
            <iyz>0</iyz>
            <izz>0.0000039</izz>
          </inertia>
        </inertial>
        <visual name="visual">
          <pose>0 0.0325 0 1.5708 0 0</pose>
          <geometry>
            <cylinder>
              <radius>0.0030</radius>
              <length>0.065</length>
            </cylinder>
          </geometry>
          <material>
            <ambient>0.0 0.0 1.0 1</ambient>
            <diffuse>0.0 0.0 1.0 1</diffuse>
            <specular>0.0 0.0 1.0 1</specular>
          </material>
        </visual>
        <!--
                <collision name='collision'>
                    <pose>0 ${arm_length / 2 } 0 1.5708 0 0</pose>
                    <geometry>
                        <cylinder>
                            <radius>0.0050</radius>
                            <length>${arm_length}</length>
                        </cylinder>
                    </geometry>
                </collision>
                -->
      </link>
      <joint name="arm3_joint" type="revolute">
        <pose relative_to="arm3_link"/>
        <parent>servo3_link</parent>
        <child>arm3_link</child>
        <axis>
          <xyz expressed_in="arm3_link">1 0 0</xyz>
          <limit>
            <lower>-1.25</lower>
            <upper>1.25</upper>
          </limit>
          <dynamics>
            <friction>0.05</friction>
            <damping>0.04</damping>
          </dynamics>
        </axis>
      </joint>
      <plugin filename="libignition-gazebo-joint-position-controller-system.so" name="ignition::gazebo::systems::JointPositionController">
        <joint_name>arm3_joint</joint_name>
        <joint_index>0</joint_index>
        <p_gain>20</p_gain>
        <i_gain>0.0</i_gain>
        <d_gain>0.0</d_gain>
      </plugin>
      <link name="servo4_link">
        <pose relative_to="base_link">0.07563 -0.036 0.033 3.14159 -0.349066 0</pose>
        <inertial>
          <!--inertial properties of the link mass, inertia matix-->
          <pose>-0.023 -0.010 0 0 0 0</pose>
          <mass>0.060</mass>
          <inertia>
            <ixx>0.00001</ixx>
            <ixy>0</ixy>
            <ixz>0</ixz>
            <iyy>0.0000065</iyy>
            <iyz>0</iyz>
            <izz>0.0000125</izz>
          </inertia>
        </inertial>
        <visual name="visual">
          <pose>-0.023 -0.010 0 0 0 0</pose>
          <geometry>
            <box>
              <size>0.030 0.040 0.020</size>
            </box>
          </geometry>
          <material>
            <ambient>0.0 1.0 0.0 1</ambient>
            <diffuse>0.0 1.0 0.0 1</diffuse>
            <specular>0.0 1.0 0.0 1</specular>
          </material>
        </visual>
        <!--
                <collision name='collision'>
                    <pose>-0.023 -0.010 0 0 0 0</pose>
                    <geometry>
                        <box>
                            <size>0.030 0.040 0.020</size>
                        </box>
                    </geometry>
                </collision>
                -->
      </link>
      <joint name="servo4_joint" type="fixed">
        <pose relative_to="servo4_link"/>
        <parent>base_link</parent>
        <child>servo4_link</child>
      </joint>
      <link name="arm4_link">
        <pose relative_to="servo4_link"/>
        <inertial>
          <mass>0.008</mass>
          <pose>0 0.0325 0 0 0 0</pose>
          <inertia>
            <ixx>0.0000041</ixx>
            <ixy>0</ixy>
            <ixz>0</ixz>
            <iyy>0.00000033</iyy>
            <iyz>0</iyz>
            <izz>0.0000039</izz>
          </inertia>
        </inertial>
        <visual name="visual">
          <pose>0 0.0325 0 1.5708 0 0</pose>
          <geometry>
            <cylinder>
              <radius>0.0030</radius>
              <length>0.065</length>
            </cylinder>
          </geometry>
          <material>
            <ambient>0.0 0.0 1.0 1</ambient>
            <diffuse>0.0 0.0 1.0 1</diffuse>
            <specular>0.0 0.0 1.0 1</specular>
          </material>
        </visual>
        <!--
                <collision name='collision'>
                    <pose>0 ${arm_length / 2 } 0 1.5708 0 0</pose>
                    <geometry>
                        <cylinder>
                            <radius>0.0050</radius>
                            <length>${arm_length}</length>
                        </cylinder>
                    </geometry>
                </collision>
                -->
      </link>
      <joint name="arm4_joint" type="revolute">
        <pose relative_to="arm4_link"/>
        <parent>servo4_link</parent>
        <child>arm4_link</child>
        <axis>
          <xyz expressed_in="arm4_link">1 0 0</xyz>
          <limit>
            <lower>-1.25</lower>
            <upper>1.25</upper>
          </limit>
          <dynamics>
            <friction>0.05</friction>
            <damping>0.04</damping>
          </dynamics>
        </axis>
      </joint>
      <plugin filename="libignition-gazebo-joint-position-controller-system.so" name="ignition::gazebo::systems::JointPositionController">
        <joint_name>arm4_joint</joint_name>
        <joint_index>0</joint_index>
        <p_gain>20</p_gain>
        <i_gain>0.0</i_gain>
        <d_gain>0.0</d_gain>
      </plugin>
      <link name="servo5_link">
        <pose relative_to="base_link">-0.00664 -0.0835 0.033 0 -0.349066 4.18879</pose>
        <inertial>
          <!--inertial properties of the link mass, inertia matix-->
          <pose>-0.023 -0.010 0 0 0 0</pose>
          <mass>0.060</mass>
          <inertia>
            <ixx>0.00001</ixx>
            <ixy>0</ixy>
            <ixz>0</ixz>
            <iyy>0.0000065</iyy>
            <iyz>0</iyz>
            <izz>0.0000125</izz>
          </inertia>
        </inertial>
        <visual name="visual">
          <pose>-0.023 -0.010 0 0 0 0</pose>
          <geometry>
            <box>
              <size>0.030 0.040 0.020</size>
            </box>
          </geometry>
          <material>
            <ambient>0.0 1.0 0.0 1</ambient>
            <diffuse>0.0 1.0 0.0 1</diffuse>
            <specular>0.0 1.0 0.0 1</specular>
          </material>
        </visual>
        <!--
                <collision name='collision'>
                    <pose>-0.023 -0.010 0 0 0 0</pose>
                    <geometry>
                        <box>
                            <size>0.030 0.040 0.020</size>
                        </box>
                    </geometry>
                </collision>
                -->
      </link>
      <joint name="servo5_joint" type="fixed">
        <pose relative_to="servo5_link"/>
        <parent>base_link</parent>
        <child>servo5_link</child>
      </joint>
      <link name="arm5_link">
        <pose relative_to="servo5_link"/>
        <inertial>
          <mass>0.008</mass>
          <pose>0 0.0325 0 0 0 0</pose>
          <inertia>
            <ixx>0.0000041</ixx>
            <ixy>0</ixy>
            <ixz>0</ixz>
            <iyy>0.00000033</iyy>
            <iyz>0</iyz>
            <izz>0.0000039</izz>
          </inertia>
        </inertial>
        <visual name="visual">
          <pose>0 0.0325 0 1.5708 0 0</pose>
          <geometry>
            <cylinder>
              <radius>0.0030</radius>
              <length>0.065</length>
            </cylinder>
          </geometry>
          <material>
            <ambient>0.0 0.0 1.0 1</ambient>
            <diffuse>0.0 0.0 1.0 1</diffuse>
            <specular>0.0 0.0 1.0 1</specular>
          </material>
        </visual>
        <!--
                <collision name='collision'>
                    <pose>0 ${arm_length / 2 } 0 1.5708 0 0</pose>
                    <geometry>
                        <cylinder>
                            <radius>0.0050</radius>
                            <length>${arm_length}</length>
                        </cylinder>
                    </geometry>
                </collision>
                -->
      </link>
      <joint name="arm5_joint" type="revolute">
        <pose relative_to="arm5_link"/>
        <parent>servo5_link</parent>
        <child>arm5_link</child>
        <axis>
          <xyz expressed_in="arm5_link">1 0 0</xyz>
          <limit>
            <lower>-1.25</lower>
            <upper>1.25</upper>
          </limit>
          <dynamics>
            <friction>0.05</friction>
            <damping>0.04</damping>
          </dynamics>
        </axis>
      </joint>
      <plugin filename="libignition-gazebo-joint-position-controller-system.so" name="ignition::gazebo::systems::JointPositionController">
        <joint_name>arm5_joint</joint_name>
        <joint_index>0</joint_index>
        <p_gain>20</p_gain>
        <i_gain>0.0</i_gain>
        <d_gain>0.0</d_gain>
      </plugin>
      <link name="servo6_link">
        <pose relative_to="base_link">-0.06899 -0.0475 0.033 3.14159 -0.349066 4.18879</pose>
        <inertial>
          <!--inertial properties of the link mass, inertia matix-->
          <pose>-0.023 -0.010 0 0 0 0</pose>
          <mass>0.060</mass>
          <inertia>
            <ixx>0.00001</ixx>
            <ixy>0</ixy>
            <ixz>0</ixz>
            <iyy>0.0000065</iyy>
            <iyz>0</iyz>
            <izz>0.0000125</izz>
          </inertia>
        </inertial>
        <visual name="visual">
          <pose>-0.023 -0.010 0 0 0 0</pose>
          <geometry>
            <box>
              <size>0.030 0.040 0.020</size>
            </box>
          </geometry>
          <material>
            <ambient>0.0 1.0 0.0 1</ambient>
            <diffuse>0.0 1.0 0.0 1</diffuse>
            <specular>0.0 1.0 0.0 1</specular>
          </material>
        </visual>
        <!--
                <collision name='collision'>
                    <pose>-0.023 -0.010 0 0 0 0</pose>
                    <geometry>
                        <box>
                            <size>0.030 0.040 0.020</size>
                        </box>
                    </geometry>
                </collision>
                -->
      </link>
      <joint name="servo6_joint" type="fixed">
        <pose relative_to="servo6_link"/>
        <parent>base_link</parent>
        <child>servo6_link</child>
      </joint>
      <link name="arm6_link">
        <pose relative_to="servo6_link"/>
        <inertial>
          <mass>0.008</mass>
          <pose>0 0.0325 0 0 0 0</pose>
          <inertia>
            <ixx>0.0000041</ixx>
            <ixy>0</ixy>
            <ixz>0</ixz>
            <iyy>0.00000033</iyy>
            <iyz>0</iyz>
            <izz>0.0000039</izz>
          </inertia>
        </inertial>
        <visual name="visual">
          <pose>0 0.0325 0 1.5708 0 0</pose>
          <geometry>
            <cylinder>
              <radius>0.0030</radius>
              <length>0.065</length>
            </cylinder>
          </geometry>
          <material>
            <ambient>0.0 0.0 1.0 1</ambient>
            <diffuse>0.0 0.0 1.0 1</diffuse>
            <specular>0.0 0.0 1.0 1</specular>
          </material>
        </visual>
        <!--
                <collision name='collision'>
                    <pose>0 ${arm_length / 2 } 0 1.5708 0 0</pose>
                    <geometry>
                        <cylinder>
                            <radius>0.0050</radius>
                            <length>${arm_length}</length>
                        </cylinder>
                    </geometry>
                </collision>
                -->
      </link>
      <joint name="arm6_joint" type="revolute">
        <pose relative_to="arm6_link"/>
        <parent>servo6_link</parent>
        <child>arm6_link</child>
        <axis>
          <xyz expressed_in="arm6_link">1 0 0</xyz>
          <limit>
            <lower>-1.25</lower>
            <upper>1.25</upper>
          </limit>
          <dynamics>
            <friction>0.05</friction>
            <damping>0.04</damping>
          </dynamics>
        </axis>
      </joint>
      <plugin filename="libignition-gazebo-joint-position-controller-system.so" name="ignition::gazebo::systems::JointPositionController">
        <joint_name>arm6_joint</joint_name>
        <joint_index>0</joint_index>
        <p_gain>20</p_gain>
        <i_gain>0.0</i_gain>
        <d_gain>0.0</d_gain>
      </plugin>
      <link name="arm1_end_link">
        <pose relative_to="arm1_link"> -0.0033 0.0682 -0.0063 0 0 0 </pose>
        <inertial>
          <mass>0.001</mass>
          <pose>0 0 0 0 0 0</pose>
          <inertia>
            <ixx>0.0000041</ixx>
            <ixy>0</ixy>
            <ixz>0</ixz>
            <iyy>0.00000033</iyy>
            <iyz>0</iyz>
            <izz>0.0000039</izz>
          </inertia>
        </inertial>
        <visual name="visual">
          <pose>0 0 0 0 0 0</pose>
          <geometry>
            <sphere>
              <radius>0.0025</radius>
            </sphere>
          </geometry>
          <material>
            <ambient>1.0 0.0 1.0 1</ambient>
            <diffuse>1.0 0.0 1.0 1</diffuse>
            <specular>1.0 0.0 1.0 1</specular>
          </material>
        </visual>
        <collision name="collision">
          <pose>0 0 0 0 0 0</pose>
          <geometry>
            <sphere>
              <radius>0.0025</radius>
            </sphere>
          </geometry>
          <surface>
            <friction>
              <ode>
                <mu>0.28</mu>
                <mu2>0.28</mu2>
              </ode>
            </friction>
          </surface>
        </collision>
      </link>
      <joint name="arm1_end_joint" type="fixed">
        <pose relative_to="arm1_end_link"/>
        <parent>arm1_link</parent>
        <child>arm1_end_link</child>
      </joint>
      <link name="arm2_end_link">
        <pose relative_to="arm2_link"> -0.0033 0.0682 0.0063 0 0 0 </pose>
        <inertial>
          <mass>0.001</mass>
          <pose>0 0 0 0 0 0</pose>
          <inertia>
            <ixx>0.0000041</ixx>
            <ixy>0</ixy>
            <ixz>0</ixz>
            <iyy>0.00000033</iyy>
            <iyz>0</iyz>
            <izz>0.0000039</izz>
          </inertia>
        </inertial>
        <visual name="visual">
          <pose>0 0 0 0 0 0</pose>
          <geometry>
            <sphere>
              <radius>0.0025</radius>
            </sphere>
          </geometry>
          <material>
            <ambient>1.0 0.0 1.0 1</ambient>
            <diffuse>1.0 0.0 1.0 1</diffuse>
            <specular>1.0 0.0 1.0 1</specular>
          </material>
        </visual>
        <collision name="collision">
          <pose>0 0 0 0 0 0</pose>
          <geometry>
            <sphere>
              <radius>0.0025</radius>
            </sphere>
          </geometry>
          <surface>
            <friction>
              <ode>
                <mu>0.28</mu>
                <mu2>0.28</mu2>
              </ode>
            </friction>
          </surface>
        </collision>
      </link>
      <joint name="arm2_end_joint" type="fixed">
        <pose relative_to="arm2_end_link"/>
        <parent>arm2_link</parent>
        <child>arm2_end_link</child>
      </joint>
      <link name="arm3_end_link">
        <pose relative_to="arm3_link"> -0.0033 0.0682 -0.0063 0 0 0 </pose>
        <inertial>
          <mass>0.001</mass>
          <pose>0 0 0 0 0 0</pose>
          <inertia>
            <ixx>0.0000041</ixx>
            <ixy>0</ixy>
            <ixz>0</ixz>
            <iyy>0.00000033</iyy>
            <iyz>0</iyz>
            <izz>0.0000039</izz>
          </inertia>
        </inertial>
        <visual name="visual">
          <pose>0 0 0 0 0 0</pose>
          <geometry>
            <sphere>
              <radius>0.0025</radius>
            </sphere>
          </geometry>
          <material>
            <ambient>1.0 0.0 1.0 1</ambient>
            <diffuse>1.0 0.0 1.0 1</diffuse>
            <specular>1.0 0.0 1.0 1</specular>
          </material>
        </visual>
        <collision name="collision">
          <pose>0 0 0 0 0 0</pose>
          <geometry>
            <sphere>
              <radius>0.0025</radius>
            </sphere>
          </geometry>
          <surface>
            <friction>
              <ode>
                <mu>0.28</mu>
                <mu2>0.28</mu2>
              </ode>
            </friction>
          </surface>
        </collision>
      </link>
      <joint name="arm3_end_joint" type="fixed">
        <pose relative_to="arm3_end_link"/>
        <parent>arm3_link</parent>
        <child>arm3_end_link</child>
      </joint>
      <link name="arm4_end_link">
        <pose relative_to="arm4_link"> -0.0033 0.0682 0.0063 0 0 0 </pose>
        <inertial>
          <mass>0.001</mass>
          <pose>0 0 0 0 0 0</pose>
          <inertia>
            <ixx>0.0000041</ixx>
            <ixy>0</ixy>
            <ixz>0</ixz>
            <iyy>0.00000033</iyy>
            <iyz>0</iyz>
            <izz>0.0000039</izz>
          </inertia>
        </inertial>
        <visual name="visual">
          <pose>0 0 0 0 0 0</pose>
          <geometry>
            <sphere>
              <radius>0.0025</radius>
            </sphere>
          </geometry>
          <material>
            <ambient>1.0 0.0 1.0 1</ambient>
            <diffuse>1.0 0.0 1.0 1</diffuse>
            <specular>1.0 0.0 1.0 1</specular>
          </material>
        </visual>
        <collision name="collision">
          <pose>0 0 0 0 0 0</pose>
          <geometry>
            <sphere>
              <radius>0.0025</radius>
            </sphere>
          </geometry>
          <surface>
            <friction>
              <ode>
                <mu>0.28</mu>
                <mu2>0.28</mu2>
              </ode>
            </friction>
          </surface>
        </collision>
      </link>
      <joint name="arm4_end_joint" type="fixed">
        <pose relative_to="arm4_end_link"/>
        <parent>arm4_link</parent>
        <child>arm4_end_link</child>
      </joint>
      <link name="arm5_end_link">
        <pose relative_to="arm5_link"> -0.0033 0.0682 -0.0063 0 0 0 </pose>
        <inertial>
          <mass>0.001</mass>
          <pose>0 0 0 0 0 0</pose>
          <inertia>
            <ixx>0.0000041</ixx>
            <ixy>0</ixy>
            <ixz>0</ixz>
            <iyy>0.00000033</iyy>
            <iyz>0</iyz>
            <izz>0.0000039</izz>
          </inertia>
        </inertial>
        <visual name="visual">
          <pose>0 0 0 0 0 0</pose>
          <geometry>
            <sphere>
              <radius>0.0025</radius>
            </sphere>
          </geometry>
          <material>
            <ambient>1.0 0.0 1.0 1</ambient>
            <diffuse>1.0 0.0 1.0 1</diffuse>
            <specular>1.0 0.0 1.0 1</specular>
          </material>
        </visual>
        <collision name="collision">
          <pose>0 0 0 0 0 0</pose>
          <geometry>
            <sphere>
              <radius>0.0025</radius>
            </sphere>
          </geometry>
          <surface>
            <friction>
              <ode>
                <mu>0.28</mu>
                <mu2>0.28</mu2>
              </ode>
            </friction>
          </surface>
        </collision>
      </link>
      <joint name="arm5_end_joint" type="fixed">
        <pose relative_to="arm5_end_link"/>
        <parent>arm5_link</parent>
        <child>arm5_end_link</child>
      </joint>
      <link name="arm6_end_link">
        <pose relative_to="arm6_link"> -0.0033 0.0682 0.0063 0 0 0 </pose>
        <inertial>
          <mass>0.001</mass>
          <pose>0 0 0 0 0 0</pose>
          <inertia>
            <ixx>0.0000041</ixx>
            <ixy>0</ixy>
            <ixz>0</ixz>
            <iyy>0.00000033</iyy>
            <iyz>0</iyz>
            <izz>0.0000039</izz>
          </inertia>
        </inertial>
        <visual name="visual">
          <pose>0 0 0 0 0 0</pose>
          <geometry>
            <sphere>
              <radius>0.0025</radius>
            </sphere>
          </geometry>
          <material>
            <ambient>1.0 0.0 1.0 1</ambient>
            <diffuse>1.0 0.0 1.0 1</diffuse>
            <specular>1.0 0.0 1.0 1</specular>
          </material>
        </visual>
        <collision name="collision">
          <pose>0 0 0 0 0 0</pose>
          <geometry>
            <sphere>
              <radius>0.0025</radius>
            </sphere>
          </geometry>
          <surface>
            <friction>
              <ode>
                <mu>0.28</mu>
                <mu2>0.28</mu2>
              </ode>
            </friction>
          </surface>
        </collision>
      </link>
      <joint name="arm6_end_joint" type="fixed">
        <pose relative_to="arm6_end_link"/>
        <parent>arm6_link</parent>
        <child>arm6_end_link</child>
      </joint>
      <plugin filename="libignition-gazebo-pose-publisher-system.so" name="ignition::gazebo::systems::PosePublisher">
        <publish_nested_model_pose>true</publish_nested_model_pose>
        <update_frequency>100</update_frequency>
      </plugin>
      <plugin filename="libignition-gazebo-joint-state-publisher-system.so" name="ignition::gazebo::systems::JointStatePublisher">
        <joint_name>arm1_joint</joint_name>
        <joint_name>arm2_joint</joint_name>
        <joint_name>arm3_joint</joint_name>
        <joint_name>arm4_joint</joint_name>
        <joint_name>arm5_joint</joint_name>
        <joint_name>arm6_joint</joint_name>
      </plugin>
    </model>
  </world>
</sdf>
